<?xml version='1.0'?>

<robot name="dd_robot">
  <link name="base_link">
    <visual>
      <origin xyz="0 0 0.6" rpy="0 0 0" />
      <geometry>
          <box size="1.2 0.5 0.25"/>
      </geometry>
    </visual>
    <collision>
      <origin xyz="0 0 0.6" rpy="0 0 0" />
      <geometry>
          <box size="1.2 0.5 0.25"/>
      </geometry>
    </collision>
    <inertial>
      <mass value="5"/>
      <inertia ixx="0.13" ixy="0.0" ixz="0.0" iyy="0.21" iyz="0.0" izz="0.13"/>
    </inertial>
  </link>

  <link name="arm_link">
    <visual>
      <origin xyz="0 0 0" rpy="0 0 0" />
      <geometry>
          <box size="1.2 0.5 0.25"/>
      </geometry>
    </visual>
    <collision>
      <origin xyz="0 0 0" rpy="0 0 0" />
      <geometry>
          <box size="1.2 0.5 0.25"/>
      </geometry>
    </collision>
    <inertial>
      <mass value="5"/>
      <inertia ixx="0.13" ixy="0.0" ixz="0.0" iyy="0.21" iyz="0.0" izz="0.13"/>
    </inertial>
  </link>

  <joint name="joint1" type="continuous">
    <parent link="base_link"/>
    <child link="arm_link"/>
    <origin xyz="0.5 0.3 0.4" rpy="0 0 0" />
    <axis xyz="0 1 0" />
  </joint>

<!--gazebo control-->

<transmission name="tran1">
    <type>transmission_interface/SimpleTransmission</type>
    <joint name="joint_left_h1">
      <hardwareInterface>EffortJointInterface</hardwareInterface>
    </joint>
    <actuator name="motor1">
      <hardwareInterface>EffortJointInterface</hardwareInterface>
      <mechanicalReduction>1</mechanicalReduction>
    </actuator>
</transmission>

<!-- ros_control plugin -->

<gazebo>
  <plugin name="gazebo_ros_control" filename="libgazebo_ros_control.so">
    <robotNamespace>/rrbot</robotNamespace>
  </plugin>
</gazebo>

</robot>
