<?xml version="1.0"?>
    <robot name="manipulator">
      <link name = "world"/>
<!--base link-->
      <link name="base_link">
       <inertial>
         <origin xyz="0 0 0.5" rpy="0 0 0"/>
         <mass value="1"/>
         <inertia ixx="100"  ixy="0"  ixz="0" iyy="100" iyz="0" izz="100" />
       </inertial>

        <visual>
          <geometry>
            <box size = "0.5 0.5 0.2"/>
          </geometry>
          <origin xyz = "0 0 0.1"/>
        </visual>
      <collision>
        <origin xyz="0 0 0" rpy="0 0 0"/>
        <geometry>
          <cylinder radius="1.2" length="0.5"/>
        </geometry>
      </collision>

      </link>
      <joint name = "joint1" type = "revolute">
        <parent link = "world"/>
        <child link = "base_link"/>
        <origin xyz = "0 0 -0.10"/>
        <limit lower ="-1.57" upper = "1.57" effort = "1000" velocity="5"/>

      </joint>

      <link name = "link1">
       <inertial>
         <origin xyz="0 0 0.5" rpy="0 0 0"/>
         <mass value="1"/>
         <inertia ixx="100"  ixy="0"  ixz="0" iyy="100" iyz="0" izz="100" />
       </inertial>

        <visual>
          <geometry>
            <cylinder length = "0.60" radius= "0.2"/>
          </geometry>
          <origin xyz = "0 0 0.30"/>
        </visual>

      <collision>
        <origin xyz="0 0 0" rpy="0 0 0"/>
        <geometry>
          <cylinder radius="0.10" length="0.60"/>
        </geometry>
      </collision>
      </link>

      <joint name= "joint2" type = "revolute">
        <parent link = "base_link"/>
        <child link = "link1"/>
        <origin xyz = "0 0 0.20"/>
        <limit lower ="-1.57" upper = "1.57" effort = "1000" velocity="5"/>
      </joint>

  <transmission name="tran1">
    <type>transmission_interface/SimpleTransmission</type>
    <joint name="joint1">
      <hardwareInterface>hardware_interface/EffortJointInterface</hardwareInterface>
    </joint>
    <actuator name="motor1">
      <hardwareInterface>EffortJointInterface</hardwareInterface>
      <mechanicalReduction>1</mechanicalReduction>
    </actuator>
  </transmission>

  <transmission name="tran2">
    <type>transmission_interface/SimpleTransmission</type>
    <joint name="joint2">
      <hardwareInterface>hardware_interface/EffortJointInterface</hardwareInterface>
    </joint>
    <actuator name="motor2">
      <hardwareInterface>EffortJointInterface</hardwareInterface>
      <mechanicalReduction>1</mechanicalReduction>
    </actuator>
  </transmission>

<gazebo>
  <plugin name="gazebo_ros_control" filename="libgazebo_ros_control.so">
    <robotNamespace>/rrbot</robotNamespace>
  </plugin>
</gazebo>


</robot>
