<?xml version="1.0"?>
<robot name="myfirst">
  <link name="base_link">
    <visual>
      <origin rpy="0 0 0" xyz="0 0 0"/>
      <geometry>
        <cylinder length="1" radius="5"/>
      </geometry>
    </visual>
    <visual>
      <origin rpy="0 0 0" xyz="0.25 0 1.5"/>
      <geometry>
        <box size="0.5 1 2"/>
      </geometry>
    </visual>
    <collision>
      <geometry>
        <cylinder length="1" radius="5"/>
	<origin rpy="0 0 0" xyz="0 0 0"/>
      </geometry>
    </collision>
    
  </link>

  <link name="inter_1">
     <visual>
       <origin rpy="0 0 0" xyz="-0.25 1 0"/>
       <geometry>
	 <box size="0.5 1 2"/>
       </geometry>
       <material name="yellow">
         <color rgba="1 1 0 1"/>
       </material>
     </visual>
     <visual>
	<origin rpy="0 0 0" xyz="-0.250 0 -0.5"/>
	<geometry>
		<box size="0.5 1 1"/>
	</geometry>
     </visual>
     <visual>
	<origin rpy="0 0 0" xyz="0.25 1 0.5"/>
	<geometry>
		<box size = "0.5 1 1"/>
	</geometry>
     </visual>
    <inertial>
      <mass value="0.1"/>
      <inertia ixx="0.067" ixy="0.0" ixz="0.0" iyy="0.067" iyz="0.0" izz="0.035"/>
    </inertial>
  </link>

  <joint name="rev_1" type="revolute">
	<origin xyz="0 0 2.5" rpy="0 0 0 "/>
	<parent link= "base_link"/>
	<child link = "inter_1"/>
	<axis xyz="1 0 0"/>
	<limit effort="30" velocity="1.0" lower="-0.45" upper="0.45" />
  </joint>

 <link name="link_2">
    <visual>
      <origin rpy="0 0 0" xyz="0 0 1.5"/>
      <geometry>
        <cylinder length="1" radius="5"/>
      </geometry>
    </visual>
    <visual>
      <origin rpy="0 0 0" xyz="0 0 0.5"/>
      <geometry>
        <box size="0.5 1 1.5"/>
      </geometry>
    </visual>
    <collision>
      <geometry>
        <cylinder length="1" radius="5"/>
	<origin rpy="0 0 0" xyz="0 0 1.5"/>
      </geometry>
    </collision>
    <inertial>
      <mass value="0.5"/>
      <inertia ixx="3.16" ixy="0.0" ixz="0.0" iyy="3.16" iyz="0.0" izz="6.25"/>
    </inertial>
  </link>
  <joint name="rev_2" type="revolute">
	<origin xyz="0 0 0.5" rpy="0 0 0 "/>
	<parent link= "inter_1"/>
	<child link = "link_2"/>
	<axis xyz="0 1 0"/>
	<limit effort="30" velocity="1.0" lower="-0.45" upper="0.45" />
  </joint>

  <link name="link_3">
    
    <visual>
      <origin rpy="0 0 0" xyz="0.25 0 1"/>
      <geometry>
        <box size="0.5 1 2"/>
      </geometry>
    </visual>
    <inertial>
      <mass value="0.1"/>
      <inertia ixx="0.01" ixy="0.0" ixz="0.0" iyy="0.042" iyz="0.0" izz="0.035"/>
    </inertial>
  </link>

  <joint name="fix_1" type="fixed">
	<origin xyz="0 0 2" rpy="0 0 0 "/>
	<parent link= "link_2"/>
	<child link = "link_3"/>
	
  </joint>

  <link name="inter_2">
     <visual>
       <origin rpy="0 0 0" xyz="-0.25 1 0.5"/>
       <geometry>
	 <box size="0.5 1 2"/>
       </geometry>
       <material name="yellow">
         <color rgba="1 1 0 1"/>
       </material>
     </visual>
     <visual>
	<origin rpy="0 0 0" xyz="-0.250 0 0"/>
	<geometry>
		<box size="0.5 1 1"/>
	</geometry>
     </visual>
     <visual>
	<origin rpy="0 0 0" xyz="0.25 1 1"/>
	<geometry>
		<box size = "0.5 1 1"/>
	</geometry>
     </visual>
    <inertial>
      <mass value="0.25"/>
      <inertia ixx="0.4" ixy="0.0" ixz="0.0" iyy="0.4" iyz="0.0" izz="0.2"/>
    </inertial>
  </link>

  <joint name="rev_3" type="revolute">
	<origin xyz="0 0 1.5" rpy="0 0 0 "/>
	<parent link= "link_3"/>
	<child link = "inter_2"/>
	<axis xyz="1 0 0"/>
	<limit effort="30" velocity="1.0" lower="-0.45" upper="0.45" />
  </joint>

 <link name="link_4">
    <visual>
      <origin rpy="0 0 0" xyz="0 0 1.5"/>
      <geometry>
        <cylinder length="1" radius="5"/>
      </geometry>
    </visual>
    <visual>
      <origin rpy="0 0 0" xyz="0 0 0.5"/>
      <geometry>
        <box size="0.5 1 1.5"/>
      </geometry>
    </visual>
    <collision>
      <geometry>
        <cylinder length="1" radius="5"/>
	<origin rpy="0 0 0" xyz="0 0 1.5"/>
      </geometry>
    </collision>
    <inertial>
      <mass value="0.1"/>
      <inertia ixx="0.067" ixy="0.0" ixz="0.0" iyy="0.067" iyz="0.0" izz="0.035"/>
    </inertial>
  </link>

  <joint name="rev_4" type="revolute">
	<origin xyz="0 0 1" rpy="0 0 0 "/>
	<parent link= "inter_2"/>
	<child link = "link_4"/>
	<axis xyz="0 1 0"/>
	<limit effort="30" velocity="1.0" lower="-0.45" upper="0.45" />
  </joint>

 

 
</robot>





