<?xml version="1.0"?>
<robot name="my_robot" xmlns:xacro="http://www.ros.org/wiki/xacro">

  <!-- Parameters -->
  <xacro:property name="w0" value="0.3" />
  <xacro:property name="l0" value="0.1" />
  <xacro:property name="l1" value="0.8" />
  <xacro:property name="r1" value="0.05" />
  <xacro:property name="w2" value="0.8" />
  <xacro:property name="l2" value="0.1" />
  <xacro:property name="ro" value="1" />
  
  <!-- Macro -->  
  <xacro:macro name="inert" params="m w h">
    <mass value="${m}" />
    <inertia ixx="${m / 12.0 * (w*w + h*h)}" ixy="0" ixz="0"
             iyy="${m / 12.0 * (w*w + h*h)}" iyz="0"
             izz="${m / 12.0 * (w*w + h*h)}" />
  </xacro:macro>

  <!-- Base -->

  <link name="world" />

  <link name="base_link">
    <visual>
      <geometry>
        <box size="${w0} ${w0} ${l0}" />
      </geometry>
      <origin xyz="0 0 ${0.5*l0}" />
    </visual>
    <collision>
      <geometry>
        <box size="${w0} ${w0} ${l0}" />
      </geometry>
      <origin xyz="0 0 ${0.5*l0}" />
    </collision>
    <inertial>
      <origin xyz="0 0 ${0.5*l0}" />
      <xacro:inert m="${ro*w0*w0*l0}" w="${w0}" h="${l0}" />      
    </inertial>
  </link>
  
  <joint name="world_to_base" type="fixed">
    <parent link="world" />
    <child  link="base_link" />
  </joint> 
  
  <!-- Joint 1 -->
  
  <link name="link_1">
    <visual>
      <geometry>
        <cylinder length="${l1}" radius="${r1}" />
      </geometry>
      <origin xyz="0 0 ${0.5*l1}" />
    </visual>
    <collision>
      <geometry>
        <cylinder length="${l1}" radius="${r1}" />
      </geometry>
      <origin xyz="0 0 ${0.5*l1}" />
    </collision>
    <inertial>
      <origin xyz="0 0 ${0.5*l1}" />
      <xacro:inert m="${3.14*r1*r1*l1*ro}" w="${2*r1}" h="${l1}" />      
    </inertial>
  </link>
  
  <joint name="base_to_link_1" type="revolute">
    <parent link="base_link" />
    <child  link="link_1" />
    <origin xyz="0 0 ${l0}" />
    <axis xyz="0 0 1" />
    <limit effort="1000.0" lower="-1.57" upper="1.57" velocity="0.5" />
  </joint>
  
  <!-- Joint 2 -->
  
  <link name="link_2">
    <visual>
      <geometry>
        <box size="${w2} ${l2} ${l2}" />
      </geometry>
    </visual>
    <collision>
      <geometry>
        <box size="${w2} ${l2} ${l2}" />
      </geometry>
    </collision>
    <inertial>
      <origin xyz="0 0 0" />
      <xacro:inert m="${w2*l2*l2}" w="${l2}" h="${w2}" />      
    </inertial>
  </link>  
  
  <joint name="link_1_to_link_2" type="prismatic">
    <parent link="link_1" />
    <child  link="link_2" />
    <origin xyz="0 0 ${l1+0.5*l2}" />
    <axis xyz="1 0 0" />
    <limit effort="1000.0" lower="-0.4" upper="0.4" velocity="0.5" />
  </joint>  
  
</robot>